2020-08-03 01:49:35,940 ERROR: Exception on /api/explore [GET] [in /home/anushrut/workload/flask-blog/blog/lib/python3.6/site-packages/flask/app.py:1761]
Traceback (most recent call last):
  File "/home/anushrut/workload/flask-blog/blog/lib/python3.6/site-packages/flask/app.py", line 2292, in wsgi_app
    response = self.full_dispatch_request()
  File "/home/anushrut/workload/flask-blog/blog/lib/python3.6/site-packages/flask/app.py", line 1815, in full_dispatch_request
    rv = self.handle_user_exception(e)
  File "/home/anushrut/workload/flask-blog/blog/lib/python3.6/site-packages/flask/app.py", line 1718, in handle_user_exception
    reraise(exc_type, exc_value, tb)
  File "/home/anushrut/workload/flask-blog/blog/lib/python3.6/site-packages/flask/_compat.py", line 35, in reraise
    raise value
  File "/home/anushrut/workload/flask-blog/blog/lib/python3.6/site-packages/flask/app.py", line 1813, in full_dispatch_request
    rv = self.dispatch_request()
  File "/home/anushrut/workload/flask-blog/blog/lib/python3.6/site-packages/flask/app.py", line 1799, in dispatch_request
    return self.view_functions[rule.endpoint](**req.view_args)
  File "/home/anushrut/workload/flask-blog/app/main/routes.py", line 26, in api_explore
    print(posts)
AttributeError: 'list' object has no attribute 'items'
2020-08-03 01:49:42,423 INFO: flask Project [in /home/anushrut/workload/flask-blog/app/__init__.py:81]
2020-08-03 01:49:45,622 ERROR: Exception on /api/explore [GET] [in /home/anushrut/workload/flask-blog/blog/lib/python3.6/site-packages/flask/app.py:1761]
Traceback (most recent call last):
  File "/home/anushrut/workload/flask-blog/blog/lib/python3.6/site-packages/flask/app.py", line 2292, in wsgi_app
    response = self.full_dispatch_request()
  File "/home/anushrut/workload/flask-blog/blog/lib/python3.6/site-packages/flask/app.py", line 1815, in full_dispatch_request
    rv = self.handle_user_exception(e)
  File "/home/anushrut/workload/flask-blog/blog/lib/python3.6/site-packages/flask/app.py", line 1718, in handle_user_exception
    reraise(exc_type, exc_value, tb)
  File "/home/anushrut/workload/flask-blog/blog/lib/python3.6/site-packages/flask/_compat.py", line 35, in reraise
    raise value
  File "/home/anushrut/workload/flask-blog/blog/lib/python3.6/site-packages/flask/app.py", line 1813, in full_dispatch_request
    rv = self.dispatch_request()
  File "/home/anushrut/workload/flask-blog/blog/lib/python3.6/site-packages/flask/app.py", line 1799, in dispatch_request
    return self.view_functions[rule.endpoint](**req.view_args)
  File "/home/anushrut/workload/flask-blog/app/main/routes.py", line 27, in api_explore
    return render_template('index.html', title=_('Explore'), posts=posts.items, next_url=next_url, prev_url=prev_url)
AttributeError: 'list' object has no attribute 'items'
2020-08-03 01:49:47,299 ERROR: Exception on /api/explore [GET] [in /home/anushrut/workload/flask-blog/blog/lib/python3.6/site-packages/flask/app.py:1761]
Traceback (most recent call last):
  File "/home/anushrut/workload/flask-blog/blog/lib/python3.6/site-packages/flask/app.py", line 2292, in wsgi_app
    response = self.full_dispatch_request()
  File "/home/anushrut/workload/flask-blog/blog/lib/python3.6/site-packages/flask/app.py", line 1815, in full_dispatch_request
    rv = self.handle_user_exception(e)
  File "/home/anushrut/workload/flask-blog/blog/lib/python3.6/site-packages/flask/app.py", line 1718, in handle_user_exception
    reraise(exc_type, exc_value, tb)
  File "/home/anushrut/workload/flask-blog/blog/lib/python3.6/site-packages/flask/_compat.py", line 35, in reraise
    raise value
  File "/home/anushrut/workload/flask-blog/blog/lib/python3.6/site-packages/flask/app.py", line 1813, in full_dispatch_request
    rv = self.dispatch_request()
  File "/home/anushrut/workload/flask-blog/blog/lib/python3.6/site-packages/flask/app.py", line 1799, in dispatch_request
    return self.view_functions[rule.endpoint](**req.view_args)
  File "/home/anushrut/workload/flask-blog/app/main/routes.py", line 27, in api_explore
    return render_template('index.html', title=_('Explore'), posts=posts.items, next_url=next_url, prev_url=prev_url)
AttributeError: 'list' object has no attribute 'items'
2020-08-03 01:51:04,968 INFO: flask Project [in /home/anushrut/workload/flask-blog/app/__init__.py:81]
2020-08-03 01:51:07,925 ERROR: Exception on /api/explore [GET] [in /home/anushrut/workload/flask-blog/blog/lib/python3.6/site-packages/flask/app.py:1761]
Traceback (most recent call last):
  File "/home/anushrut/workload/flask-blog/blog/lib/python3.6/site-packages/flask/app.py", line 2292, in wsgi_app
    response = self.full_dispatch_request()
  File "/home/anushrut/workload/flask-blog/blog/lib/python3.6/site-packages/flask/app.py", line 1815, in full_dispatch_request
    rv = self.handle_user_exception(e)
  File "/home/anushrut/workload/flask-blog/blog/lib/python3.6/site-packages/flask/app.py", line 1718, in handle_user_exception
    reraise(exc_type, exc_value, tb)
  File "/home/anushrut/workload/flask-blog/blog/lib/python3.6/site-packages/flask/_compat.py", line 35, in reraise
    raise value
  File "/home/anushrut/workload/flask-blog/blog/lib/python3.6/site-packages/flask/app.py", line 1813, in full_dispatch_request
    rv = self.dispatch_request()
  File "/home/anushrut/workload/flask-blog/blog/lib/python3.6/site-packages/flask/app.py", line 1799, in dispatch_request
    return self.view_functions[rule.endpoint](**req.view_args)
  File "/home/anushrut/workload/flask-blog/app/main/routes.py", line 27, in api_explore
    next_url = url_for('main.explore', page=posts.next_num) if posts.has_next else None
AttributeError: 'list' object has no attribute 'has_next'
2020-08-03 01:55:35,511 INFO: flask Project [in /home/anushrut/workload/flask-blog/app/__init__.py:81]
2020-08-03 01:55:43,565 ERROR: Exception on /api/explore [GET] [in /home/anushrut/workload/flask-blog/blog/lib/python3.6/site-packages/flask/app.py:1761]
Traceback (most recent call last):
  File "/home/anushrut/workload/flask-blog/blog/lib/python3.6/site-packages/flask/app.py", line 2292, in wsgi_app
    response = self.full_dispatch_request()
  File "/home/anushrut/workload/flask-blog/blog/lib/python3.6/site-packages/flask/app.py", line 1815, in full_dispatch_request
    rv = self.handle_user_exception(e)
  File "/home/anushrut/workload/flask-blog/blog/lib/python3.6/site-packages/flask/app.py", line 1718, in handle_user_exception
    reraise(exc_type, exc_value, tb)
  File "/home/anushrut/workload/flask-blog/blog/lib/python3.6/site-packages/flask/_compat.py", line 35, in reraise
    raise value
  File "/home/anushrut/workload/flask-blog/blog/lib/python3.6/site-packages/flask/app.py", line 1813, in full_dispatch_request
    rv = self.dispatch_request()
  File "/home/anushrut/workload/flask-blog/blog/lib/python3.6/site-packages/flask/app.py", line 1799, in dispatch_request
    return self.view_functions[rule.endpoint](**req.view_args)
  File "/home/anushrut/workload/flask-blog/app/main/routes.py", line 30, in api_explore
    return jsonify(posts.items)
  File "/home/anushrut/workload/flask-blog/blog/lib/python3.6/site-packages/flask/json/__init__.py", line 321, in jsonify
    dumps(data, indent=indent, separators=separators) + '\n',
  File "/home/anushrut/workload/flask-blog/blog/lib/python3.6/site-packages/flask/json/__init__.py", line 179, in dumps
    rv = _json.dumps(obj, **kwargs)
  File "/usr/lib/python3.6/json/__init__.py", line 238, in dumps
    **kw).encode(obj)
  File "/usr/lib/python3.6/json/encoder.py", line 199, in encode
    chunks = self.iterencode(o, _one_shot=True)
  File "/usr/lib/python3.6/json/encoder.py", line 257, in iterencode
    return _iterencode(o, 0)
  File "/home/anushrut/workload/flask-blog/blog/lib/python3.6/site-packages/flask/json/__init__.py", line 81, in default
    return _json.JSONEncoder.default(self, o)
  File "/usr/lib/python3.6/json/encoder.py", line 180, in default
    o.__class__.__name__)
TypeError: Object of type 'Post' is not JSON serializable
2020-08-03 02:13:49,584 INFO: flask Project [in /home/anushrut/workload/flask-blog/app/__init__.py:81]
2020-08-03 02:13:51,711 INFO: flask Project [in /home/anushrut/workload/flask-blog/app/__init__.py:81]
2020-08-03 02:13:59,087 ERROR: Exception on /api/explore [GET] [in /home/anushrut/workload/flask-blog/blog/lib/python3.6/site-packages/flask/app.py:1761]
Traceback (most recent call last):
  File "/home/anushrut/workload/flask-blog/blog/lib/python3.6/site-packages/flask/app.py", line 2292, in wsgi_app
    response = self.full_dispatch_request()
  File "/home/anushrut/workload/flask-blog/blog/lib/python3.6/site-packages/flask/app.py", line 1815, in full_dispatch_request
    rv = self.handle_user_exception(e)
  File "/home/anushrut/workload/flask-blog/blog/lib/python3.6/site-packages/flask/app.py", line 1718, in handle_user_exception
    reraise(exc_type, exc_value, tb)
  File "/home/anushrut/workload/flask-blog/blog/lib/python3.6/site-packages/flask/_compat.py", line 35, in reraise
    raise value
  File "/home/anushrut/workload/flask-blog/blog/lib/python3.6/site-packages/flask/app.py", line 1813, in full_dispatch_request
    rv = self.dispatch_request()
  File "/home/anushrut/workload/flask-blog/blog/lib/python3.6/site-packages/flask/app.py", line 1799, in dispatch_request
    return self.view_functions[rule.endpoint](**req.view_args)
  File "/home/anushrut/workload/flask-blog/app/main/routes.py", line 27, in api_explore
    data = Post.to_collection_dict(Post.query, page, per_page, 'api_explore')
AttributeError: type object 'Post' has no attribute 'to_collection_dict'
