2020-08-03 01:32:04,505 INFO: flask Project [in /home/anushrut/workload/flask-blog/app/__init__.py:81]
2020-08-03 01:32:15,757 INFO: flask Project [in /home/anushrut/workload/flask-blog/app/__init__.py:81]
2020-08-03 01:44:07,045 INFO: flask Project [in /home/anushrut/workload/flask-blog/app/__init__.py:81]
2020-08-03 01:44:10,125 INFO: flask Project [in /home/anushrut/workload/flask-blog/app/__init__.py:81]
2020-08-03 01:44:47,509 ERROR: Exception on /api/explore [GET] [in /home/anushrut/workload/flask-blog/blog/lib/python3.6/site-packages/flask/app.py:1761]
Traceback (most recent call last):
  File "/home/anushrut/workload/flask-blog/blog/lib/python3.6/site-packages/flask/app.py", line 2292, in wsgi_app
    response = self.full_dispatch_request()
  File "/home/anushrut/workload/flask-blog/blog/lib/python3.6/site-packages/flask/app.py", line 1815, in full_dispatch_request
    rv = self.handle_user_exception(e)
  File "/home/anushrut/workload/flask-blog/blog/lib/python3.6/site-packages/flask/app.py", line 1718, in handle_user_exception
    reraise(exc_type, exc_value, tb)
  File "/home/anushrut/workload/flask-blog/blog/lib/python3.6/site-packages/flask/_compat.py", line 35, in reraise
    raise value
  File "/home/anushrut/workload/flask-blog/blog/lib/python3.6/site-packages/flask/app.py", line 1813, in full_dispatch_request
    rv = self.dispatch_request()
  File "/home/anushrut/workload/flask-blog/blog/lib/python3.6/site-packages/flask/app.py", line 1799, in dispatch_request
    return self.view_functions[rule.endpoint](**req.view_args)
  File "/home/anushrut/workload/flask-blog/app/main/routes.py", line 26, in api_explore
    return jsonify(posts)
  File "/home/anushrut/workload/flask-blog/blog/lib/python3.6/site-packages/flask/json/__init__.py", line 321, in jsonify
    dumps(data, indent=indent, separators=separators) + '\n',
  File "/home/anushrut/workload/flask-blog/blog/lib/python3.6/site-packages/flask/json/__init__.py", line 179, in dumps
    rv = _json.dumps(obj, **kwargs)
  File "/usr/lib/python3.6/json/__init__.py", line 238, in dumps
    **kw).encode(obj)
  File "/usr/lib/python3.6/json/encoder.py", line 199, in encode
    chunks = self.iterencode(o, _one_shot=True)
  File "/usr/lib/python3.6/json/encoder.py", line 257, in iterencode
    return _iterencode(o, 0)
  File "/home/anushrut/workload/flask-blog/blog/lib/python3.6/site-packages/flask/json/__init__.py", line 81, in default
    return _json.JSONEncoder.default(self, o)
  File "/usr/lib/python3.6/json/encoder.py", line 180, in default
    o.__class__.__name__)
TypeError: Object of type 'Post' is not JSON serializable
2020-08-03 01:44:52,576 ERROR: Exception on /api/explore [GET] [in /home/anushrut/workload/flask-blog/blog/lib/python3.6/site-packages/flask/app.py:1761]
Traceback (most recent call last):
  File "/home/anushrut/workload/flask-blog/blog/lib/python3.6/site-packages/flask/app.py", line 2292, in wsgi_app
    response = self.full_dispatch_request()
  File "/home/anushrut/workload/flask-blog/blog/lib/python3.6/site-packages/flask/app.py", line 1815, in full_dispatch_request
    rv = self.handle_user_exception(e)
  File "/home/anushrut/workload/flask-blog/blog/lib/python3.6/site-packages/flask/app.py", line 1718, in handle_user_exception
    reraise(exc_type, exc_value, tb)
  File "/home/anushrut/workload/flask-blog/blog/lib/python3.6/site-packages/flask/_compat.py", line 35, in reraise
    raise value
  File "/home/anushrut/workload/flask-blog/blog/lib/python3.6/site-packages/flask/app.py", line 1813, in full_dispatch_request
    rv = self.dispatch_request()
  File "/home/anushrut/workload/flask-blog/blog/lib/python3.6/site-packages/flask/app.py", line 1799, in dispatch_request
    return self.view_functions[rule.endpoint](**req.view_args)
  File "/home/anushrut/workload/flask-blog/app/main/routes.py", line 26, in api_explore
    return jsonify(posts)
  File "/home/anushrut/workload/flask-blog/blog/lib/python3.6/site-packages/flask/json/__init__.py", line 321, in jsonify
    dumps(data, indent=indent, separators=separators) + '\n',
  File "/home/anushrut/workload/flask-blog/blog/lib/python3.6/site-packages/flask/json/__init__.py", line 179, in dumps
    rv = _json.dumps(obj, **kwargs)
  File "/usr/lib/python3.6/json/__init__.py", line 238, in dumps
    **kw).encode(obj)
  File "/usr/lib/python3.6/json/encoder.py", line 199, in encode
    chunks = self.iterencode(o, _one_shot=True)
  File "/usr/lib/python3.6/json/encoder.py", line 257, in iterencode
    return _iterencode(o, 0)
  File "/home/anushrut/workload/flask-blog/blog/lib/python3.6/site-packages/flask/json/__init__.py", line 81, in default
    return _json.JSONEncoder.default(self, o)
  File "/usr/lib/python3.6/json/encoder.py", line 180, in default
    o.__class__.__name__)
TypeError: Object of type 'Post' is not JSON serializable
2020-08-03 01:48:21,186 INFO: flask Project [in /home/anushrut/workload/flask-blog/app/__init__.py:81]
2020-08-03 01:48:23,043 INFO: flask Project [in /home/anushrut/workload/flask-blog/app/__init__.py:81]
2020-08-03 01:48:31,099 ERROR: Exception on /api/explore [GET] [in /home/anushrut/workload/flask-blog/blog/lib/python3.6/site-packages/flask/app.py:1761]
Traceback (most recent call last):
  File "/home/anushrut/workload/flask-blog/blog/lib/python3.6/site-packages/flask/app.py", line 2292, in wsgi_app
    response = self.full_dispatch_request()
  File "/home/anushrut/workload/flask-blog/blog/lib/python3.6/site-packages/flask/app.py", line 1815, in full_dispatch_request
    rv = self.handle_user_exception(e)
  File "/home/anushrut/workload/flask-blog/blog/lib/python3.6/site-packages/flask/app.py", line 1718, in handle_user_exception
    reraise(exc_type, exc_value, tb)
  File "/home/anushrut/workload/flask-blog/blog/lib/python3.6/site-packages/flask/_compat.py", line 35, in reraise
    raise value
  File "/home/anushrut/workload/flask-blog/blog/lib/python3.6/site-packages/flask/app.py", line 1813, in full_dispatch_request
    rv = self.dispatch_request()
  File "/home/anushrut/workload/flask-blog/blog/lib/python3.6/site-packages/flask/app.py", line 1799, in dispatch_request
    return self.view_functions[rule.endpoint](**req.view_args)
  File "/home/anushrut/workload/flask-blog/app/main/routes.py", line 26, in api_explore
    return jsonify(posts.items)
AttributeError: 'list' object has no attribute 'items'
2020-08-03 01:48:33,559 ERROR: Exception on /api/explore [GET] [in /home/anushrut/workload/flask-blog/blog/lib/python3.6/site-packages/flask/app.py:1761]
Traceback (most recent call last):
  File "/home/anushrut/workload/flask-blog/blog/lib/python3.6/site-packages/flask/app.py", line 2292, in wsgi_app
    response = self.full_dispatch_request()
  File "/home/anushrut/workload/flask-blog/blog/lib/python3.6/site-packages/flask/app.py", line 1815, in full_dispatch_request
    rv = self.handle_user_exception(e)
  File "/home/anushrut/workload/flask-blog/blog/lib/python3.6/site-packages/flask/app.py", line 1718, in handle_user_exception
    reraise(exc_type, exc_value, tb)
  File "/home/anushrut/workload/flask-blog/blog/lib/python3.6/site-packages/flask/_compat.py", line 35, in reraise
    raise value
  File "/home/anushrut/workload/flask-blog/blog/lib/python3.6/site-packages/flask/app.py", line 1813, in full_dispatch_request
    rv = self.dispatch_request()
  File "/home/anushrut/workload/flask-blog/blog/lib/python3.6/site-packages/flask/app.py", line 1799, in dispatch_request
    return self.view_functions[rule.endpoint](**req.view_args)
  File "/home/anushrut/workload/flask-blog/app/main/routes.py", line 26, in api_explore
    return jsonify(posts.items)
AttributeError: 'list' object has no attribute 'items'
2020-08-03 01:49:33,682 ERROR: Exception on /api/explore [GET] [in /home/anushrut/workload/flask-blog/blog/lib/python3.6/site-packages/flask/app.py:1761]
Traceback (most recent call last):
  File "/home/anushrut/workload/flask-blog/blog/lib/python3.6/site-packages/flask/app.py", line 2292, in wsgi_app
    response = self.full_dispatch_request()
  File "/home/anushrut/workload/flask-blog/blog/lib/python3.6/site-packages/flask/app.py", line 1815, in full_dispatch_request
    rv = self.handle_user_exception(e)
  File "/home/anushrut/workload/flask-blog/blog/lib/python3.6/site-packages/flask/app.py", line 1718, in handle_user_exception
    reraise(exc_type, exc_value, tb)
  File "/home/anushrut/workload/flask-blog/blog/lib/python3.6/site-packages/flask/_compat.py", line 35, in reraise
    raise value
  File "/home/anushrut/workload/flask-blog/blog/lib/python3.6/site-packages/flask/app.py", line 1813, in full_dispatch_request
    rv = self.dispatch_request()
  File "/home/anushrut/workload/flask-blog/blog/lib/python3.6/site-packages/flask/app.py", line 1799, in dispatch_request
    return self.view_functions[rule.endpoint](**req.view_args)
  File "/home/anushrut/workload/flask-blog/app/main/routes.py", line 26, in api_explore
    print(posts)
AttributeError: 'list' object has no attribute 'items'
